<mujoco model="x2">
  <compiler angle="radian"/>
  <default>
    <joint damping="0.1" armature="0.01" frictionloss="0.01" actuatorfrcrange="-60 60"/>
    <default class="humanoid">
      <default class="collision">
        <geom group="3" contype="1" conaffinity="1" />
      </default>
      <default class="visual">
        <geom contype="0" conaffinity="0" group="2" />
      </default>
      <site size="0.01" rgba="1 0 0 1" group="4"/>
    </default>
  </default>
  <option iterations="3" ls_iterations="5" timestep="0.002" integrator="Euler">
    <flag eulerdamp="disable"/> <!-- this is not the reason for too much memory-->
  </option>
  <asset>
    <mesh name="pelvis_link" file="meshes/pelvis_link.STL"/>
    <mesh name="L_hip_yaw_link" file="meshes/L_hip_yaw_link.STL"/>
    <mesh name="L_hip_roll_link" file="meshes/L_hip_roll_link.STL"/>
    <mesh name="L_hip_pitch_link" file="meshes/L_hip_pitch_link.STL"/>
    <mesh name="L_knee_pitch_link" file="meshes/L_knee_pitch_link.STL"/>
    <mesh name="L_ankle_pitch_link" file="meshes/L_ankle_pitch_link.STL"/>
    <mesh name="R_hip_yaw_link" file="meshes/R_hip_yaw_link.STL"/>
    <mesh name="R_hip_roll_link" file="meshes/R_hip_roll_link.STL"/>
    <mesh name="R_hip_pitch_link" file="meshes/R_hip_pitch_link.STL"/>
    <mesh name="R_knee_pitch_link" file="meshes/R_knee_pitch_link.STL"/>
    <mesh name="R_ankle_pitch_link" file="meshes/R_ankle_pitch_link.STL"/>
    <mesh name="waist_yaw_link" file="meshes/waist_yaw_link.STL"/>
    <mesh name="torso_link" file="meshes/torso_link.STL"/>
    <mesh name="logo_link" file="meshes/logo_link.STL"/>
    <mesh name="head_link" file="meshes/head_link.STL"/>
    <mesh name="L_shoulder_pitch_link" file="meshes/L_shoulder_pitch_link.STL"/>
    <mesh name="L_shoulder_roll_link" file="meshes/L_shoulder_roll_link.STL"/>
    <mesh name="L_shoulder_yaw_link" file="meshes/L_shoulder_yaw_link.STL"/>
    <mesh name="L_elbow_pitch_link" file="meshes/L_elbow_pitch_link.STL"/>
    <mesh name="R_shoulder_pitch_link" file="meshes/R_shoulder_pitch_link.STL"/>
    <mesh name="R_shoulder_roll_link" file="meshes/R_shoulder_roll_link.STL"/>
    <mesh name="R_shoulder_yaw_link" file="meshes/R_shoulder_yaw_link.STL"/>
    <mesh name="R_elbow_pitch_link" file="meshes/R_elbow_pitch_link.STL"/>
  </asset>
  <worldbody>
    <light name="spotlight" target="pelvis_link" pos="0 0 2" dir="0 0 -1." cutoff="30" mode="targetbodycom"/>
    <body name="pelvis_link" pos="0 0 0.91" childclass="humanoid">
      <joint name="pelvis_link" type="free" limited="false" actuatorfrclimited="false"/>
      <camera name="front" pos="1.210 -0.435 0.32" xyaxes="0.342 0.940 0.000 -0.321 0.117 0.940" mode="trackcom"/>
      <camera name="track" pos="1.35 -1.70 0.5" xyaxes="0.814 0.580 0.000 -0.140 0.196 0.971" mode="trackcom"/>
      <site name="imu"/>
      <inertial pos="-0.000780925 -1.61312e-05 0.320098" quat="0.999982 -6.6303e-05 0.00594371 0.000195653" mass="14.8692" diaginertia="0.548526 0.426111 0.226041"/>
      <geom type="mesh" rgba="1 1 1 1" mesh="pelvis_link" class="visual"/>
      <geom pos="0 0 0.08375" type="mesh" rgba="1 1 1 1" mesh="waist_yaw_link" class="visual"/>
      <geom pos="0 0 0.1205"  type="mesh" rgba="0.823529 0.823529 0.823529 1" mesh="torso_link" class="visual"/>
      <geom pos="0 0 0.1205"  type="mesh" rgba="1 0 0 1" mesh="logo_link" class="visual"/>
      <geom pos="0 0 0.485"   type="mesh" rgba="1 1 1 1" mesh="head_link" class="visual"/>
      <geom pos="-0.01 0.144770 0.43584" quat="0.996195 0.0871543 0 0" type="mesh" rgba="1 1 1 1" mesh="L_shoulder_pitch_link" class="visual"/>
      <geom pos="-0.01 0.204843 0.446432" type="mesh" rgba="1 1 1 1" mesh="L_shoulder_roll_link" class="visual"/>
      <geom pos="-0.01 0.204843 0.334432" type="mesh" rgba="1 1 1 1" mesh="L_shoulder_yaw_link" class="visual"/>
      <geom pos="0 0.204843 0.161432" quat="0.707388 0 -0.706825 0" type="mesh" rgba="1 1 1 1" mesh="L_elbow_pitch_link" class="visual"/>
      <geom pos="-0.01 -0.14477 0.43584" quat="0.996195 -0.0871543 0 0" type="mesh" rgba="1 1 1 1" mesh="R_shoulder_pitch_link" class="visual"/>
      <geom pos="-0.01 -0.204843 0.446432" type="mesh" rgba="1 1 1 1" mesh="R_shoulder_roll_link" class="visual"/>
      <geom pos="-0.010039 -0.204843 0.334432" type="mesh" rgba="1 1 1 1" mesh="R_shoulder_yaw_link" class="visual"/>
      <geom pos="3.6e-08 -0.204843 0.161432" quat="0.707388 0 -0.706825 0" type="mesh" rgba="1 1 1 1" mesh="R_elbow_pitch_link" class="visual"/>
      <body name="L_hip_yaw_link">
        <inertial pos="-0.0005618 0.019831 0.00885104" quat="0.416547 0.491409 -0.566922 0.513426" mass="0.841" diaginertia="0.00175713 0.00175343 0.000573392"/>
        <joint name="L_hip_yaw" pos="0 0 0" axis="0 0 1" range="-0.7854 0.7854" actuatorfrcrange="-30 30" damping="4"/>
        <geom type="mesh" rgba="1 1 1 1" mesh="L_hip_yaw_link" class="visual"/>
        <body name="L_hip_roll_link" pos="-0.0095 0.1 0">
          <inertial pos="-0.0324725 0.00017925 -0.0726484" quat="0.655395 -0.252501 -0.247695 0.667344" mass="2.667" diaginertia="0.0108627 0.0094793 0.00603247"/>
          <joint name="L_hip_roll" pos="0 0 0" axis="1 0 0" range="-0.349 0.524" actuatorfrcrange="-45 45" damping="5"/>
          <geom type="mesh" rgba="1 1 1 1" mesh="L_hip_roll_link" class="visual"/>
          <body name="L_hip_pitch_link" pos="0.0085 -0.001 -0.11">
            <inertial pos="0.00382921 0 -0.185484" quat="0.706562 0.0278169 0.0278188 0.706557" mass="1.664" diaginertia="0.0148443 0.0145077 0.0030868"/>
            <joint name="L_hip_pitch" pos="0 0 0" axis="0 -1 0" range="-0.526 2.4434" actuatorfrcrange="-45 45" damping="5"/>
            <geom type="mesh" rgba="1 1 1 1" mesh="L_hip_pitch_link" class="visual"/>
            <body name="L_knee_pitch_link" pos="0 0 -0.35">
              <inertial pos="0.00140265 0 -0.15876" quat="0.706958 -0.0143173 -0.0143148 0.706965" mass="1.125" diaginertia="0.00999859 0.00987345 0.00100926"/>
              <joint name="L_knee_pitch" pos="0 0 0" axis="0 -1 0" range="-2.3561 0" actuatorfrcrange="-60 60" damping="5"/>
              <geom type="mesh" rgba="1 1 1 1" mesh="L_knee_pitch_link" class="visual"/>
              <body name="L_ankle_pitch_link" pos="0 0 -0.35">
<!--            <inertial pos="0.0393988 -0.000237278 -0.0784143" quat="0.92388 0 0.382683 0" mass="0.556154" diaginertia="0.0100029 0.01 0.0099971"/>
                <inertial pos="0.0393988 -0.000237278 -0.0784143" quat="0 0.705556 0 0.708654" mass="0.556154" diaginertia="0.00260004 0.00215 0.000549961"/>-->
                <inertial pos="0.0393988 -0.000237278 -0.0784143" quat="0.92388 0 0.382683 0" mass="0.556154" diaginertia="0.01 0.01 0.01"/>

                <joint name="L_ankle_pitch" pos="0 0 0" axis="0 -1 0" range="-1.2217 1.2217" actuatorfrcrange="-30 30" damping="1"/>
                <geom type="mesh" rgba="1 1 1 1" mesh="L_ankle_pitch_link" class="visual"/>
                <!--
                <geom name="l_foot00" size="0.005" pos="-0.118  0     -0.095" rgba="1 1 1 1" class="collision"/>
                <geom name="l_foot01" size="0.005" pos="-0.075  0.039 -0.095" rgba="1 1 1 1" class="collision"/>
                <geom name="l_foot02" size="0.005" pos="-0.075 -0.039 -0.095" rgba="1 1 1 1" class="collision"/>
                <geom name="l_foot03" size="0.005" pos="-0.025  0.037 -0.095" rgba="1 1 1 1" class="collision"/>
                <geom name="l_foot04" size="0.005" pos="-0.025 -0.032 -0.095" rgba="1 1 1 1" class="collision"/>
                <geom name="l_foot05" size="0.005" pos=" 0.025  0.041 -0.095" rgba="1 1 1 1" class="collision"/>
                <geom name="l_foot06" size="0.005" pos=" 0.025 -0.033 -0.095" rgba="1 1 1 1" class="collision"/>
                <geom name="l_foot07" size="0.005" pos="0.08    0.047 -0.095" rgba="1 1 1 1" class="collision"/>
                <geom name="l_foot08" size="0.005" pos="0.08   -0.047 -0.095" rgba="1 1 1 1" class="collision"/>
                <geom name="l_foot09" size="0.005" pos="0.12    0.038 -0.095" rgba="1 1 1 1" class="collision"/>
                <geom name="l_foot10" size="0.005" pos="0.12   -0.045 -0.095" rgba="1 1 1 1" class="collision"/>
                <geom name="l_foot11" size="0.005" pos="0.15   -0.01  -0.095" rgba="1 1 1 1" class="collision"/>
                -->
                <!-- cylinders not yet supported in mjx
                <geom type="cylinder" name="l_foot00" size="0.042 0.005" pos="-0.08 0.0 -0.095" rgba="1 0 0 1" class="collision"/>
                <geom type="cylinder" name="l_foot01" size="0.050 0.005" pos="0.1 0.002 -0.095" rgba="1 0 0 1" class="collision"/>
                <geom type="box" name="l_foot02" size="0.1 0.039 0.005" pos="0.01 0 -0.095" rgba="1 0 0 1" class="collision"/>
                -->
                <geom type="box" name="l_foot00" size="0.14 0.039 0.005" pos="0.023 0 -0.095" rgba="1 0 0 1" class="collision"/>

                <site name="l_foot" pos="0 0 -0.095" />
              </body>
            </body>
          </body>
        </body>
      </body>
      <body name="R_hip_yaw_link">
        <inertial pos="-0.00116447 -0.0404495 0" quat="0.707002 0.707002 -0.0121739 -0.0121739" mass="0.219202" diaginertia="0.000598763 0.000555362 0.000156982"/>
        <joint name="R_hip_yaw" pos="0 0 0" axis="0 0 -1" range="-0.7854 0.7854" actuatorfrcrange="-30 30" damping="4"/>
        <geom type="mesh" rgba="1 1 1 1" mesh="R_hip_yaw_link" class="visual"/>
        <body name="R_hip_roll_link" pos="-0.0095 -0.1 0">
          <inertial pos="-0.0324725 0.00017925 -0.0726484" quat="0.655395 -0.252501 -0.247695 0.667344" mass="2.667" diaginertia="0.0108627 0.0094793 0.00603247"/>
          <joint name="R_hip_roll" pos="0 0 0" axis="-1 0 0" range="-0.349 0.524" actuatorfrcrange="-45 45" damping="5"/>
          <geom type="mesh" rgba="1 1 1 1" mesh="R_hip_roll_link" class="visual"/>
          <body name="R_hip_pitch_link" pos="0.0085 -0.001 -0.11">
            <inertial pos="0.00382921 0 -0.185485" quat="0.706557 0.0278188 0.0278169 0.706562" mass="1.664" diaginertia="0.0148443 0.0145077 0.0030868"/>
            <joint name="R_hip_pitch" pos="0 0 0" axis="0 -1 0" range="-0.526 2.4434" actuatorfrcrange="-45 45" damping="5"/>
            <geom type="mesh" rgba="1 1 1 1" mesh="R_hip_pitch_link" class="visual"/>
            <body name="R_knee_pitch_link" pos="0 0 -0.35">
              <inertial pos="0.00140265 0 -0.15876" quat="0.706965 -0.0143148 -0.0143173 0.706958" mass="1.125" diaginertia="0.00999859 0.00987345 0.00100926"/>
              <joint name="R_knee_pitch" pos="0 0 0" axis="0 -1 0" range="-2.3561 0" actuatorfrcrange="-60 60" damping="5"/>
              <geom type="mesh" rgba="1 1 1 1" mesh="R_knee_pitch_link" class="visual"/>
              <body name="R_ankle_pitch_link" pos="0 0 -0.35">
<!--            <inertial pos="0.0393998 0.00023708 -0.0784145" quat="0.92388 0 0.382683 0" mass="0.556161" diaginertia="0.0100029 0.01 0.0099971"/>
                <inertial pos="0.0393998 0.00023708 -0.0784145" quat="0 0.705556 0 0.708654" mass="0.556161" diaginertia="0.00260004 0.00215 0.000549961"/>-->
                <inertial pos="0.0393998 0.00023708 -0.0784145" quat="0.92388 0 0.382683 0" mass="0.556161" diaginertia="0.01 0.01 0.01"/>
                <joint name="R_ankle_pitch" pos="0 0 0" axis="0 -1 0" range="-1.2217 1.2217" actuatorfrcrange="-30 30" damping="1"/>
                <geom type="mesh" rgba="1 1 1 1" mesh="R_ankle_pitch_link" class="visual"/>
                <!--
                <geom name="r_foot00" size="0.005" pos="-0.118  0     -0.095" rgba="1 1 1 1" class="collision"/>
                <geom name="r_foot01" size="0.005" pos="-0.075  0.039 -0.095" rgba="1 1 1 1" class="collision"/>
                <geom name="r_foot02" size="0.005" pos="-0.075 -0.039 -0.095" rgba="1 1 1 1" class="collision"/>
                <geom name="r_foot03" size="0.005" pos="-0.025  0.032 -0.095" rgba="1 1 1 1" class="collision"/>
                <geom name="r_foot04" size="0.005" pos="-0.025 -0.037 -0.095" rgba="1 1 1 1" class="collision"/>
                <geom name="r_foot05" size="0.005" pos=" 0.025  0.033 -0.095" rgba="1 1 1 1" class="collision"/>
                <geom name="r_foot06" size="0.005" pos=" 0.025 -0.041 -0.095" rgba="1 1 1 1" class="collision"/>
                <geom name="r_foot07" size="0.005" pos="0.08    0.047 -0.095" rgba="1 1 1 1" class="collision"/>
                <geom name="r_foot08" size="0.005" pos="0.08   -0.047 -0.095" rgba="1 1 1 1" class="collision"/>
                <geom name="r_foot09" size="0.005" pos="0.12    0.045 -0.095" rgba="1 1 1 1" class="collision"/>
                <geom name="r_foot10" size="0.005" pos="0.12   -0.038 -0.095" rgba="1 1 1 1" class="collision"/>
                <geom name="r_foot11" size="0.005" pos="0.15    0.01  -0.095" rgba="1 1 1 1" class="collision"/>
                -->
                <!-- cylinders not yet supported in mjx
                <geom type="cylinder" name="r_foot00" size="0.042 0.005" pos="-0.08 0.0 -0.095" rgba="1 0 0 1" class="collision"/>
                <geom type="cylinder" name="r_foot01" size="0.050 0.005" pos="0.1 -0.002 -0.095" rgba="1 0 0 1" class="collision"/>
                <geom type="box" name="r_foot02" size="0.1 0.039 0.005" pos="0.01 0 -0.095" rgba="1 0 0 1" class="collision"/>
                -->
                <geom type="box" name="r_foot00" size="0.14 0.039 0.005" pos="0.023 0 -0.095" rgba="1 0 0 1" class="collision"/>

                <site name="r_foot" pos="0 0 -0.095" />
              </body>
            </body>
          </body>
        </body>
      </body>
    </body>
  </worldbody>
  <actuator>
    <position name="juL" joint="L_hip_yaw"       kp="160" kv="0"/> <!-- Leg Left -->
    <position name="jsL" joint="L_hip_roll"      kp="200" kv="0"/>
    <position name="jhL" joint="L_hip_pitch"     kp="200" kv="0"/>
    <position name="jkL" joint="L_knee_pitch"    kp="200" kv="0"/>
    <position name="jpL" joint="L_ankle_pitch"   kp="30"  kv="0"/>

    <position name="juR" joint="R_hip_yaw"       kp="160" kv="0"/> <!-- Leg Right -->
    <position name="jsR" joint="R_hip_roll"      kp="200" kv="0"/>
    <position name="jhR" joint="R_hip_pitch"     kp="200" kv="0"/>
    <position name="jkR" joint="R_knee_pitch"    kp="200" kv="0"/>
    <position name="jpR" joint="R_ankle_pitch"   kp="30"  kv="0"/>
  </actuator>
  <sensor>
    <gyro site="imu" name="gyro"/>
    <velocimeter site="imu" name="local_linvel"/>
    <accelerometer site="imu" name="accelerometer"/>
    <framezaxis objtype="site" objname="imu" name="upvector"/>
    <framexaxis objtype="site" objname="imu" name="forwardvector"/>
    <framelinvel objtype="site" objname="imu" name="global_linvel"/>
    <frameangvel objtype="site" objname="imu" name="global_angvel"/>
    <framepos objtype="site" objname="imu" name="position"/>
    <framequat objtype="site" objname="imu" name="orientation"/>
    <framelinvel objtype="site" objname="l_foot" name="l_foot_global_linvel"/>
    <framelinvel objtype="site" objname="r_foot" name="r_foot_global_linvel"/>
    <framexaxis objtype="site" objname="l_foot" name="l_foot_upvector"/>
    <framexaxis objtype="site" objname="r_foot" name="r_foot_upvector"/>
    <framepos objtype="site" objname="l_foot" name="l_foot_pos"/>
    <framepos objtype="site" objname="r_foot" name="r_foot_pos"/>
  </sensor>
</mujoco>
